Workbook

Sheet Notes
A1: Solar EV Charging System - Illustrative Design Calculations
A2: Supports the conceptual portfolio design. CONCEPTUAL - NOT A CONSTRUCTION-READY DESIGN.
A4: Purpose | B4: Replaces TBD placeholders with a transparent, formula-driven worked example so the architecture drawings are backed by numbers.
A5: How to use | B5: Change blue cells on the Inputs sheet (yellow = key assumptions). Every other sheet recalculates. Review PASS/FAIL checks.
A6: Colour code | B6: Blue text = input. Black = formula. Yellow fill = key design assumption. Green/red = PASS/FAIL check.
A7: Sheets | B7: Inputs | PV_Sizing | BESS_Sizing | EV_Pack | Cable_Protection | Ref_Tables
A8: Status of values | B8: All module, inverter, battery and cable values are ILLUSTRATIVE. They are not taken from a real datasheet or standard edition and must be replaced with verified data.
A9: Not included | B9: Short-circuit and fault-level studies, protection coordination, earthing design, arc-flash, thermal design, BMS algorithms, grid-connection requirements, and standards compliance.
A10: Grid | B10: A grid-connected 400 V / 50 Hz supply is ASSUMED for the energy balance. The grid interface is not yet on EVD-001 to EVD-010.
A12: Overall check status | B12: =IF(COUNTIF(PV_Sizing!B5:B80,"FAIL")+COUNTIF(BESS_Sizing!B5:B60,"FAIL")+COUNTIF(EV_Pack!B5:B60,"FAIL")+COUNTIF(Cable_Protection!P5:Q12,"FAIL")+COUNTIF(Cable_Protection!I12:I14,"FAIL")=0,"ALL CHECKS PASS","CHECK FAILURES: "&(COUNTIF(PV_Sizing!B5:B80,"FAIL")+COUNTIF(BESS_Sizing!B5:B60,"FAIL")+COUNTIF(EV_Pack!B5:B60,"FAIL")+COUNTIF(Cable_Protection!P5:Q12,"FAIL")+COUNTIF(Cable_Protection!I12:I14,"FAIL"))) -> ALL CHECKS PASS
A13: Number of checks | B13: =COUNTIF(PV_Sizing!B5:B80,"PASS")+COUNTIF(BESS_Sizing!B5:B60,"PASS")+COUNTIF(EV_Pack!B5:B60,"PASS")+COUNTIF(Cable_Protection!P5:Q12,"PASS")+COUNTIF(Cable_Protection!I12:I14,"PASS") -> 24

Sheet Inputs
A1: Inputs - illustrative example values
A2: Blue = editable input. Yellow fill = key design assumption. All values are ILLUSTRATIVE, not from a real site or datasheet.
A4: Parameter | B4: Description | C4: Value | D4: Unit | E4: Basis / note
A5: 1. Site and charging load
A6: v_ll | B6: Site supply, line-to-line | C6: 400 | D6: V | E6: Assumed 3-phase 400 V / 50 Hz grid-connected site (grid interface itself not drawn yet)
A7: v_ph | B7: Site supply, line-to-neutral | C7: 230 | D7: V | E7: Assumed
A8: n_ch | B8: Number of AC charging points | C8: 2 | D8: - | E8: Assumed
A9: i_ch | B9: Rated current per charging point | C9: 32 | D9: A | E9: Assumed Mode 3 AC charger, single-phase
A10: sessions | B10: Charging sessions per day (whole site) | C10: 4 | D10: - | E10: Assumed
A11: e_session | B11: AC energy drawn per session | C11: 20 | D11: kWh | E11: Assumed
A12: solar_share | B12: Target share of daily energy served by PV | C12: 0.5 | D12: fraction | E12: Design target
A13: bess_share | B13: Share of daily energy served via BESS (evening/night) | C13: 0.3 | D13: fraction | E13: Design target - energy shifted by storage
A14: 2. Solar resource and losses
A15: psh | B15: Peak sun hours (equivalent full-sun hours per day) | C15: 4.5 | D15: h/day | E15: Assumed - replace with site data (e.g. PVGIS / measured)
A16: pr | B16: PV performance ratio | C16: 0.8 | D16: - | E16: Typical planning value
A17: path_eff | B17: Energy path efficiency (PV -> load incl. BESS losses) | C17: 0.95 | D17: - | E17: Assumed blended value
A18: t_min | B18: Minimum site ambient temperature | C18: 10 | D18: degC | E18: Assumed - set from site climate data
A19: t_cell | B19: Maximum PV cell temperature | C19: 70 | D19: degC | E19: Assumed
A20: 3. PV module (illustrative 550 Wp class)
A21: p_mod | B21: Module rated power | C21: 550 | D21: Wp | E21: Illustrative - replace with datasheet
A22: voc | B22: Open-circuit voltage Voc (STC) | C22: 49.5 | D22: V | E22: Illustrative
A23: vmp | B23: Voltage at max power Vmp (STC) | C23: 41.5 | D23: V | E23: Illustrative
A24: isc | B24: Short-circuit current Isc (STC) | C24: 14 | D24: A | E24: Illustrative
A25: imp | B25: Current at max power Imp (STC) | C25: 13.26 | D25: A | E25: Illustrative
A26: k_voc | B26: Temperature coefficient of Voc | C26: -0.27 | D26: %/degC | E26: Illustrative
A27: k_vmp | B27: Temperature coefficient of Vmp (approx.) | C27: -0.29 | D27: %/degC | E27: Illustrative
A28: fuse_max | B28: Module max series fuse rating | C28: 25 | D28: A | E28: Illustrative
A29: mod_len | B29: Modules per string | C29: 12 | D29: - | E29: Design choice - checked against inverter window
A30: 4. Solar inverter (illustrative 12 kW, 3-phase)
A31: p_inv | B31: Inverter rated AC output | C31: 12 | D31: kW | E31: Illustrative
A32: v_dc_max | B32: Max DC input voltage | C32: 1000 | D32: V | E32: Illustrative
A33: mppt_min | B33: MPPT voltage range - min | C33: 200 | D33: V | E33: Illustrative
A34: mppt_max | B34: MPPT voltage range - max | C34: 800 | D34: V | E34: Illustrative
A35: i_mppt | B35: Max operating DC current per MPPT input | C35: 30 | D35: A | E35: Illustrative
A36: i_isc_max | B36: Max short-circuit current per MPPT input | C36: 40 | D36: A | E36: Illustrative
A37: dcac_min | B37: Acceptable DC/AC ratio - min | C37: 1 | D37: - | E37: Design guideline
A38: dcac_max | B38: Acceptable DC/AC ratio - max | C38: 1.3 | D38: - | E38: Design guideline
A39: 5. Stationary BESS (illustrative LFP rack modules)
A40: m_kwh | B40: Battery module nominal energy | C40: 5.12 | D40: kWh | E40: Illustrative (16S x 3.2 V x 100 Ah)
A41: m_v | B41: Battery module nominal voltage | C41: 51.2 | D41: V | E41: Illustrative
...

Sheet PV_Sizing
A1: Energy demand, PV array and inverter sizing
A2: Illustrative worked example - not a construction design
A4: Parameter | B4: Value | C4: Unit | D4: Formula / note
A5: 1. Charging energy demand
A6: Power per charging point | B6: =Inputs!$C$7*Inputs!$C$9/1000 -> 7.36 | C6: kW | D6: V x I (single-phase)
A7: Peak site charging demand | B7: =Inputs!$C$8*PV_Sizing!$B$6 -> 14.72 | C7: kW | D7: All points in use at once
A8: Daily charging energy | B8: =Inputs!$C$10*Inputs!$C$11 -> 80 | C8: kWh/day | D8: Sessions x energy per session
A9: Daily energy to be served from PV (direct + via BESS) | B9: =PV_Sizing!$B$8*Inputs!$C$12 -> 40 | C9: kWh/day
A10: Daily energy to be served via BESS | B10: =PV_Sizing!$B$8*Inputs!$C$13 -> 24 | C10: kWh/day
A11: 2. PV array sizing
A12: Required PV capacity | B12: =PV_Sizing!$B$9/(Inputs!$C$15*Inputs!$C$16*Inputs!$C$17) -> 11.695906 | C12: kWp | D12: E / (PSH x PR x path efficiency)
A13: Modules required | B13: =ROUNDUP(PV_Sizing!$B$12*1000/Inputs!$C$21,0) -> 22 | C13: -
A14: Number of strings | B14: =ROUNDUP(PV_Sizing!$B$13/Inputs!$C$29,0) -> 2 | C14: - | D14: Rounded up to whole strings
A15: Installed modules | B15: =PV_Sizing!$B$14*Inputs!$C$29 -> 24 | C15: -
A16: Installed PV capacity | B16: =PV_Sizing!$B$15*Inputs!$C$21/1000 -> 13.2 | C16: kWp
A17: Estimated daily PV yield | B17: =PV_Sizing!$B$16*Inputs!$C$15*Inputs!$C$16 -> 47.52 | C17: kWh/day
A18: PV energy reaching load (after path losses) | B18: =PV_Sizing!$B$17*Inputs!$C$17 -> 45.144 | C18: kWh/day
A19: Estimated daily grid import | B19: =MAX(0,PV_Sizing!$B$8-PV_Sizing!$B$18) -> 34.856 | C19: kWh/day | D19: Grid interface to be added to drawings
A20: Estimated solar share of charging energy | B20: =MIN(1,PV_Sizing!$B$18/PV_Sizing!$B$8) -> 0.5643 | C20: fraction
A21: Check: installed PV meets required capacity | B21: =IF(PV_Sizing!$B$16>=PV_Sizing!$B$12,"PASS","FAIL") -> PASS
A22: 3. String voltage and current checks
A23: Module Voc at minimum temperature | B23: =Inputs!$C$22*(1+Inputs!$C$26/100*(Inputs!$C$18-25)) -> 51.50475 | C23: V
A24: Module Vmp at maximum cell temperature | B24: =Inputs!$C$23*(1+Inputs!$C$27/100*(Inputs!$C$19-25)) -> 36.08425 | C24: V
A25: Module Vmp at minimum temperature | B25: =Inputs!$C$23*(1+Inputs!$C$27/100*(Inputs!$C$18-25)) -> 43.30525 | C25: V
A26: String Voc (cold) | B26: =Inputs!$C$29*PV_Sizing!$B$23 -> 618.057 | C26: V
A27: String Vmp (hot) | B27: =Inputs!$C$29*PV_Sizing!$B$24 -> 433.011 | C27: V
A28: String Vmp (cold) | B28: =Inputs!$C$29*PV_Sizing!$B$25 -> 519.663 | C28: V
A29: String Vmp (STC) - reference voltage for cable calcs | B29: =Inputs!$C$29*Inputs!$C$23 -> 498 | C29: V
A30: Check: string Voc (cold) <= inverter max DC voltage | B30: =IF(PV_Sizing!$B$26<=Inputs!$C$32,"PASS","FAIL") -> PASS
A31: Check: string Vmp (hot) >= MPPT minimum | B31: =IF(PV_Sizing!$B$27>=Inputs!$C$33,"PASS","FAIL") -> PASS
A32: Check: string Vmp (cold) <= MPPT maximum | B32: =IF(PV_Sizing!$B$28<=Inputs!$C$34,"PASS","FAIL") -> PASS
A33: Array Isc (strings paralleled on one MPPT input) | B33: =PV_Sizing!$B$14*Inputs!$C$24 -> 28 | C33: A
A34: Array Imp (strings paralleled on one MPPT input) | B34: =PV_Sizing!$B$14*Inputs!$C$25 -> 26.52 | C34: A
A35: Check: array Isc <= MPPT input max Isc | B35: =IF(PV_Sizing!$B$33<=Inputs!$C$36,"PASS","FAIL") -> PASS
A36: Check: array Imp <= MPPT input max current | B36: =IF(PV_Sizing!$B$34<=Inputs!$C$35,"PASS","FAIL") -> PASS
A37: 4. Inverter
A38: DC/AC ratio | B38: =PV_Sizing!$B$16/Inputs!$C$31 -> 1.1 | C38: -
A39: Check: DC/AC ratio within guideline | B39: =IF(AND(PV_Sizing!$B$38>=Inputs!$C$37,PV_Sizing!$B$38<=Inputs!$C$38),"PASS","FAIL") -> PASS
A40: Inverter AC output current | B40: =Inputs!$C$31*1000/(SQRT(3)*Inputs!$C$6) -> 17.320508 | C40: A | D40: P / (sqrt3 x V)

Sheet BESS_Sizing
A1: Stationary BESS sizing
A2: Illustrative worked example - not a construction design
A4: Parameter | B4: Value | C4: Unit | D4: Formula / note
A5: 1. Energy sizing
A6: Energy to be delivered by BESS per day | B6: =PV_Sizing!$B$10 -> 24 | C6: kWh/day | D6: From PV_Sizing
A7: Required nominal capacity | B7: =BESS_Sizing!$B$6/(Inputs!$C$44*Inputs!$C$45) -> 28.070175 | C7: kWh | D7: E / (DoD x discharge efficiency)
A8: Modules required | B8: =ROUNDUP(BESS_Sizing!$B$7/Inputs!$C$40,0) -> 6 | C8: -
A9: Parallel strings | B9: =ROUNDUP(BESS_Sizing!$B$8/Inputs!$C$46,0) -> 2 | C9: - | D9: Modules per string set on Inputs
A10: Installed modules | B10: =Inputs!$C$46*BESS_Sizing!$B$9 -> 6 | C10: -
A11: Installed nominal capacity | B11: =BESS_Sizing!$B$10*Inputs!$C$40 -> 30.72 | C11: kWh
A12: Usable energy at AC side | B12: =BESS_Sizing!$B$11*Inputs!$C$44*Inputs!$C$45 -> 26.2656 | C12: kWh
A13: Check: usable energy >= daily BESS requirement | B13: =IF(BESS_Sizing!$B$12>=BESS_Sizing!$B$6,"PASS","FAIL") -> PASS
A14: 2. DC bus and PCS
A15: DC string nominal voltage | B15: =Inputs!$C$46*Inputs!$C$41 -> 153.6 | C15: V
A16: DC string maximum voltage | B16: =Inputs!$C$46*Inputs!$C$42 -> 175.2 | C16: V
A17: DC string minimum voltage | B17: =Inputs!$C$46*Inputs!$C$43 -> 134.4 | C17: V
A18: Check: DC voltage range inside PCS window | B18: =IF(AND(BESS_Sizing!$B$16<=Inputs!$C$50,BESS_Sizing!$B$17>=Inputs!$C$49),"PASS","FAIL") -> PASS
A19: PCS DC current at rated power (nominal voltage) | B19: =Inputs!$C$47*1000/(Inputs!$C$48*BESS_Sizing!$B$15) -> 67.117698 | C19: A
A20: DC current per parallel string | B20: =BESS_Sizing!$B$19/BESS_Sizing!$B$9 -> 33.558849 | C20: A
A21: PCS AC current at rated power | B21: =Inputs!$C$47*1000/(SQRT(3)*Inputs!$C$6) -> 14.433757 | C21: A | D21: 3-phase
A22: C-rate at rated PCS power | B22: =Inputs!$C$47/BESS_Sizing!$B$11 -> 0.32552083 | C22: 1/h
A23: Check: C-rate <= module continuous limit | B23: =IF(BESS_Sizing!$B$22<=Inputs!$C$51,"PASS","FAIL") -> PASS
A24: Runtime at rated PCS power | B24: =BESS_Sizing!$B$12/Inputs!$C$47 -> 2.62656 | C24: h
A25: PCS power as share of peak charging demand | B25: =MIN(1,Inputs!$C$47/PV_Sizing!$B$7) -> 0.67934783 | C25: fraction | D25: Informational - remainder from PV/grid

Sheet EV_Pack
A1: EV battery pack and AC charging session
A2: Illustrative worked example - not a vehicle design
A4: Parameter | B4: Value | C4: Unit | D4: Formula / note
A5: 1. Pack configuration
A6: Pack nominal voltage | B6: =Inputs!$C$57*Inputs!$C$53 -> 350.4 | C6: V
A7: Pack maximum voltage | B7: =Inputs!$C$57*Inputs!$C$54 -> 403.2 | C7: V
A8: Pack minimum voltage | B8: =Inputs!$C$57*Inputs!$C$55 -> 288 | C8: V
A9: Pack capacity | B9: =Inputs!$C$58*Inputs!$C$56 -> 170 | C9: Ah
A10: Pack nominal energy | B10: =EV_Pack!$B$6*EV_Pack!$B$9/1000 -> 59.568 | C10: kWh
A11: Pack usable energy | B11: =EV_Pack!$B$10*Inputs!$C$59 -> 53.6112 | C11: kWh
A12: Total cells | B12: =Inputs!$C$57*Inputs!$C$58 -> 192 | C12: -
A13: 2. HV bus currents (for contactor / fuse selection input)
A14: Peak discharge current (worst case at minimum voltage) | B14: =Inputs!$C$60*1000/EV_Pack!$B$8 -> 520.83333 | C14: A
A15: Continuous discharge current (nominal voltage) | B15: =Inputs!$C$61*1000/EV_Pack!$B$6 -> 171.23288 | C15: A
A16: Peak C-rate | B16: =EV_Pack!$B$14/EV_Pack!$B$9 -> 3.0637255 | C16: 1/h
A17: Minimum contactor continuous rating (1.25 x continuous) | B17: =1.25*EV_Pack!$B$15 -> 214.0411 | C17: A | D17: Selection margin assumed
A18: 3. AC charging session
A19: AC power drawn (limited by charger and on-board charger) | B19: =MIN(Inputs!$C$62,PV_Sizing!$B$6) -> 7.36 | C19: kW
A20: Power into battery | B20: =EV_Pack!$B$19*Inputs!$C$63 -> 6.7712 | C20: kW
A21: Energy into battery per session | B21: =Inputs!$C$11*Inputs!$C$63 -> 18.4 | C21: kWh
A22: Charging time for one session | B22: =Inputs!$C$11/EV_Pack!$B$19 -> 2.7173913 | C22: h
A23: Charging current into pack (nominal voltage) | B23: =EV_Pack!$B$20*1000/EV_Pack!$B$6 -> 19.324201 | C23: A
A24: SOC added per session (of usable energy) | B24: =EV_Pack!$B$21/EV_Pack!$B$11 -> 0.34321187 | C24: fraction
A25: Check: pack usable energy >= energy per session | B25: =IF(EV_Pack!$B$11>=EV_Pack!$B$21,"PASS","FAIL") -> PASS

Sheet Ref_Tables
A1: Reference tables
A2: Indicative values approximating IEC 60364-5-52 / BS 7671 reference method C, PVC-insulated copper, 30 degC ambient. VERIFY against the current standard edition before any real use.
A4: Size (mm2) | B4: Current capacity, 2 loaded conductors (A) - single-phase / DC | C4: Current capacity, 3 loaded conductors (A) - 3-phase | E4: Standard device ratings (A)
A5: 1.5 | B5: 19.5 | C5: 17.5 | E5: 6
A6: 2.5 | B6: 27 | C6: 24 | E6: 10
A7: 4 | B7: 36 | C7: 32 | E7: 16
A8: 6 | B8: 46 | C8: 41 | E8: 20
A9: 10 | B9: 63 | C9: 57 | E9: 25
A10: 16 | B10: 85 | C10: 76 | E10: 32
A11: 25 | B11: 112 | C11: 96 | E11: 40
A12: 35 | B12: 138 | C12: 119 | E12: 50
A13: 50 | B13: 168 | C13: 144 | E13: 63
A14: 70 | B14: 213 | C14: 184 | E14: 80
A15: 95 | B15: 258 | C15: 223 | E15: 100
A16: 120 | B16: 299 | C16: 259 | E16: 125
E17: 160
E18: 200
E19: 250

Sheet Cable_Protection
A1: Cable sizing and protective device selection
A2: Links to Cable_Schedule.xlsx (CBL-xxx). Blue = input. Size = larger of ampacity-based and voltage-drop-based minimum. Reactance and short-circuit withstand are NOT included.
A4: Cable ID | B4: Circuit | C4: Type | D4: Voltage (V) | E4: Design current for protection Ib (A) | F4: Operating current for V-drop (A) | G4: Length one-way (m) | H4: V-drop limit (%) | I4: Protective device In (A) | J4: Derating factor | K4: Min size by ampacity (mm2) | L4: Min size by V-drop (mm2) | M4: Selected size (mm2) | N4: Derated capacity Iz (A) | O4: V-drop (%) | P4: Ib <= In <= Iz | Q4: V-drop OK
A5: CBL-001 | B5: PV string -> PV combiner (per string) | C5: DC | D5: =PV_Sizing!$B$29 -> 498 | E5: =1.25*Inputs!$C$24 -> 17.5 | F5: =Inputs!$C$25 -> 13.26 | G5: 20 | H5: 0.01 | I5: =INDEX(Ref_Tables!$E$5:$E$19,COUNTIF(Ref_Tables!$E$5:$E$19,"<"&E5)+1) -> 20 | J5: =Inputs!$C$66*Inputs!$C$67 -> 0.696 | K5: =INDEX(Ref_Tables!$A$5:$A$16,SUMPRODUCT(--(INDEX(Ref_Tables!$B$5:$C$16,0,IF(C5="3ph",2,1))<I5/J5))+1) -> 4 | L5: =INDEX(Ref_Tables!$A$5:$A$16,COUNTIF(Ref_Tables!$A$5:$A$16,"<"&(IF(C5="3ph",SQRT(3),2)*G5*F5*Inputs!$C$65/(H5*D5)))+1) -> 2.5 | M5: =MAX(K5,L5) -> 4 | N5: =INDEX(Ref_Tables!$B$5:$C$16,MATCH(M5,Ref_Tables!$A$5:$A$16,0),IF(C5="3ph",2,1))*J5 -> 25.056 | O5: =IF(C5="3ph",SQRT(3),2)*G5*F5*Inputs!$C$65/(M5*D5) -> 0.0059909639 | P5: =IF(AND(E5<=I5,I5<=N5),"PASS","FAIL") -> PASS | Q5: =IF(O5<=H5,"PASS","FAIL") -> PASS
A6: CBL-002 | B6: PV combiner -> solar inverter | C6: DC | D6: =PV_Sizing!$B$29 -> 498 | E6: =1.25*Inputs!$C$24*PV_Sizing!$B$14 -> 35 | F6: =Inputs!$C$25*PV_Sizing!$B$14 -> 26.52 | G6: 15 | H6: 0.01 | I6: =INDEX(Ref_Tables!$E$5:$E$19,COUNTIF(Ref_Tables!$E$5:$E$19,"<"&E6)+1) -> 40 | J6: =Inputs!$C$66*Inputs!$C$67 -> 0.696 | K6: =INDEX(Ref_Tables!$A$5:$A$16,SUMPRODUCT(--(INDEX(Ref_Tables!$B$5:$C$16,0,IF(C6="3ph",2,1))<I6/J6))+1) -> 10 | L6: =INDEX(Ref_Tables!$A$5:$A$16,COUNTIF(Ref_Tables!$A$5:$A$16,"<"&(IF(C6="3ph",SQRT(3),2)*G6*F6*Inputs!$C$65/(H6*D6)))+1) -> 4 | M6: =MAX(K6,L6) -> 10 | N6: =INDEX(Ref_Tables!$B$5:$C$16,MATCH(M6,Ref_Tables!$A$5:$A$16,0),IF(C6="3ph",2,1))*J6 -> 43.848 | O6: =IF(C6="3ph",SQRT(3),2)*G6*F6*Inputs!$C$65/(M6*D6) -> 0.0035945783 | P6: =IF(AND(E6<=I6,I6<=N6),"PASS","FAIL") -> PASS | Q6: =IF(O6<=H6,"PASS","FAIL") -> PASS
A7: CBL-003 | B7: Solar inverter -> AC distribution | C7: 3ph | D7: =Inputs!$C$6 -> 400 | E7: =PV_Sizing!$B$40 -> 17.320508 | F7: =PV_Sizing!$B$40 -> 17.320508 | G7: 10 | H7: 0.01 | I7: =INDEX(Ref_Tables!$E$5:$E$19,COUNTIF(Ref_Tables!$E$5:$E$19,"<"&E7)+1) -> 20 | J7: =Inputs!$C$66*Inputs!$C$67 -> 0.696 | K7: =INDEX(Ref_Tables!$A$5:$A$16,SUMPRODUCT(--(INDEX(Ref_Tables!$B$5:$C$16,0,IF(C7="3ph",2,1))<I7/J7))+1) -> 4 | L7: =INDEX(Ref_Tables!$A$5:$A$16,COUNTIF(Ref_Tables!$A$5:$A$16,"<"&(IF(C7="3ph",SQRT(3),2)*G7*F7*Inputs!$C$65/(H7*D7)))+1) -> 2.5 | M7: =MAX(K7,L7) -> 4 | N7: =INDEX(Ref_Tables!$B$5:$C$16,MATCH(M7,Ref_Tables!$A$5:$A$16,0),IF(C7="3ph",2,1))*J7 -> 22.272 | O7: =IF(C7="3ph",SQRT(3),2)*G7*F7*Inputs!$C$65/(M7*D7) -> 0.00421875 | P7: =IF(AND(E7<=I7,I7<=N7),"PASS","FAIL") -> PASS | Q7: =IF(O7<=H7,"PASS","FAIL") -> PASS
A8: CBL-004 | B8: AC distribution -> BESS PCS | C8: 3ph | D8: =Inputs!$C$6 -> 400 | E8: =BESS_Sizing!$B$21 -> 14.433757 | F8: =BESS_Sizing!$B$21 -> 14.433757 | G8: 15 | H8: 0.015 | I8: =INDEX(Ref_Tables!$E$5:$E$19,COUNTIF(Ref_Tables!$E$5:$E$19,"<"&E8)+1) -> 16 | J8: =Inputs!$C$66*Inputs!$C$67 -> 0.696 | K8: =INDEX(Ref_Tables!$A$5:$A$16,SUMPRODUCT(--(INDEX(Ref_Tables!$B$5:$C$16,0,IF(C8="3ph",2,1))<I8/J8))+1) -> 2.5 | L8: =INDEX(Ref_Tables!$A$5:$A$16,COUNTIF(Ref_Tables!$A$5:$A$16,"<"&(IF(C8="3ph",SQRT(3),2)*G8*F8*Inputs!$C$65/(H8*D8)))+1) -> 1.5 | M8: =MAX(K8,L8) -> 2.5 | N8: =INDEX(Ref_Tables!$B$5:$C$16,MATCH(M8,Ref_Tables!$A$5:$A$16,0),IF(C8="3ph",2,1))*J8 -> 16.704 | O8: =IF(C8="3ph",SQRT(3),2)*G8*F8*Inputs!$C$65/(M8*D8) -> 0.0084375 | P8: =IF(AND(E8<=I8,I8<=N8),"PASS","FAIL") -> PASS | Q8: =IF(O8<=H8,"PASS","FAIL") -> PASS
A9: CBL-005 | B9: AC distribution -> EV charger (per charger) | C9: 1ph | D9: =Inputs!$C$7 -> 230 | E9: =Inputs!$C$9 -> 32 | F9: =Inputs!$C$9 -> 32 | G9: 30 | H9: 0.03 | I9: =INDEX(Ref_Tables!$E$5:$E$19,COUNTIF(Ref_Tables!$E$5:$E$19,"<"&E9)+1) -> 32 | J9: =Inputs!$C$66*Inputs!$C$67 -> 0.696 | K9: =INDEX(Ref_Tables!$A$5:$A$16,SUMPRODUCT(--(INDEX(Ref_Tables!$B$5:$C$16,0,IF(C9="3ph",2,1))<I9/J9))+1) -> 6 | L9: =INDEX(Ref_Tables!$A$5:$A$16,COUNTIF(Ref_Tables!$A$5:$A$16,"<"&(IF(C9="3ph",SQRT(3),2)*G9*F9*Inputs!$C$65/(H9*D9)))+1) -> 10 | M9: =MAX(K9,L9) -> 10 | N9: =INDEX(Ref_Tables!$B$5:$C$16,MATCH(M9,Ref_Tables!$A$5:$A$16,0),IF(C9="3ph",2,1))*J9 -> 43.848 | O9: =IF(C9="3ph",SQRT(3),2)*G9*F9*Inputs!$C$65/(M9*D9) -> 0.018782609 | P9: =IF(AND(E9<=I9,I9<=N9),"PASS","FAIL") -> PASS | Q9: =IF(O9<=H9,"PASS","FAIL") -> PASS
A10: CBL-006 | B10: EV charger -> EV (charging cable) | C10: 1ph | D10: =Inputs!$C$7 -> 230 | E10: =Inputs!$C$9 -> 32 | F10: =Inputs!$C$9 -> 32 | G10: 5 | H10: 0.01 | I10: =INDEX(Ref_Tables!$E$5:$E$19,COUNTIF(Ref_Tables!$E$5:$E$19,"<"&E10)+1) -> 32 | J10: =Inputs!$C$66*Inputs!$C$67 -> 0.696 | K10: =INDEX(Ref_Tables!$A$5:$A$16,SUMPRODUCT(--(INDEX(Ref_Tables!$B$5:$C$16,0,IF(C10="3ph",2,1))<I10/J10))+1) -> 6 | L10: =INDEX(Ref_Tables!$A$5:$A$16,COUNTIF(Ref_Tables!$A$5:$A$16,"<"&(IF(C10="3ph",SQRT(3),2)*G10*F10*Inputs!$C$65/(H10*D10)))+1) -> 4 | M10: =MAX(K10,L10) -> 6 | N10: =INDEX(Ref_Tables!$B$5:$C$16,MATCH(M10,Ref_Tables!$A$5:$A$16,0),IF(C10="3ph",2,1))*J10 -> 32.016 | O10: =IF(C10="3ph",SQRT(3),2)*G10*F10*Inputs!$C$65/(M10*D10) -> 0.0052173913 | P10: =IF(AND(E10<=I10,I10<=N10),"PASS","FAIL") -> PASS | Q10: =IF(O10<=H10,"PASS","FAIL") -> PASS
A12: Additional check
A13: String protective device <= module max series fuse rating | I13: =IF(I5<=Inputs!$C$28,"PASS","FAIL") -> PASS
A15: Notes:
A16: 1. Ib for PV circuits = 1.25 x Isc (x number of parallel strings); AC/charger circuits use rated current. Protective device In = next standard rating >= Ib.
A17: 2. Voltage drop uses resistance only (copper at operating temperature). Short-circuit withstand, earthing, and fault-loop checks are NOT done.
A18: 3. DC protective devices must be DC-rated (e.g. gPV fuses / DC isolators). String-level protection is shown for illustration; whether it is required depends on the standard and the module reverse-current rating.
A19: 4. CBL-007 to CBL-010 (EV HV and BMS cables) are vehicle-side and not sized in this workbook.
